Workbook

Sheet Pytania
A1: Kod | B1: Poziom | C1: Gałąź | D1: Pytanie | E1: Status | F1: Nieoczywiste | G1: Dlaczego ważne | H1: Zależy od | I1: Źródło | J1: Zgłoszenia społeczności | K1: Pochodzenie | L1: Moje notatki | M1: Odpowiedź
A2: A1 | B2: Pytanie | C2: A · Cel i miara sukcesu | D2: Jakie konkretne rezultaty ma dawać każdy z moich systemów i komu mają służyć? | E2: Otwarte | F2: nie | G2: Bez nazwanego rezultatu nie da się stwierdzić, czy Claude „się słucha” ani czy audyt coś przeoczył; każda ocena staje się wrażeniem. | I2: analiza własna; KB O0 §6 „Apparent understanding” [SOURCE: CC best-practices] | K2: Analiza własna
A3: A2 | B3: Pytanie | C3: A · Cel i miara sukcesu | D3: Po czym, niezależnie od zapewnień Claude, poznam, że zadanie zostało wykonane dobrze? | E3: Otwarte | F3: nie | G3: Bez sprawdzalnych kryteriów odbioru „gotowe” znaczy tylko „Claude tak twierdzi”, a dwie oceny tej samej pracy wychodzą różnie. | H3: A1 | I3: KB O0 §6 „False done”; https://www.anthropic.com/engineering/demystifying-evals-for-ai-agents („A good task is one where two domain experts would independently reach the same pass/fail verdict.”) | K3: Baza wiedzy repo
A4: A3 | B4: Pytanie | C4: A · Cel i miara sukcesu | D4: Które błędy są dla mnie najdroższe, a które mogę tolerować? | E4: Otwarte | F4: tak | G4: Bez tego kontrola jest rozłożona na ślepo: za droga tam, gdzie błąd nic nie kosztuje, i za słaba tam, gdzie kosztuje najwięcej. | H4: A1 | I4: KB O0 §8 (przegląd w świeżym kontekście opłaca się tam, gdzie błąd kosztuje więcej niż przegląd) | K4: Baza wiedzy repo
A5: A4 | B5: Pytanie | C5: A · Cel i miara sukcesu | D5: Które zadania w ogóle nadają się do powierzenia Claude, a które lepiej zrobić samemu lub innym narzędziem? | E5: Otwarte | F5: tak | G5: Źle dobrane zadanie daje pozorną pracę, której sprawdzanie trwa dłużej niż zrobienie jej samemu. | H5: A1, A3 | I5: analiza własna; KB O0 §8 (małe, iteracyjne zadania taniej w głównym oknie) | K5: Analiza własna
A6: A4.1 | B6: Podpytanie | C6: A · Cel i miara sukcesu | D6: Jak duże zadanie mogę dać jednej sesji lub jednemu agentowi, zanim jakość zacznie spadać, i po czym poznam, że trzeba je podzielić? | E6: Otwarte | F6: tak | G6: Zbyt duże zadanie zapełnia pamięć roboczą modelu; Claude zaczyna „zapominać” wcześniejsze polecenia i częściej się myli, a ja widzę tylko końcowe „gotowe”. | H6: A4, G3 | I6: https://code.claude.com/docs/en/best-practices („When the context window is getting full, Claude may start "forgetting" earlier instructions or making more mistakes.”); KB O0 §1 (stopniowy spadek jakości, bez progu liczbowego) | K6: Dokumentacja Anthropic
A7: A5 | B7: Pytanie | C7: A · Cel i miara sukcesu | D7: Które decyzje zostawiam wyłącznie sobie, a kiedy Claude ma przerwać pracę i zapytać? | E7: Otwarte | F7: nie | G7: Bez tej granicy Claude albo rozstrzyga sprawy, które należą do mnie (także nieodwracalne), albo zatrzymuje się bez potrzeby. | H7: A3 | I7: KB O0 §3, §8; https://platform.claude.com/docs/en/build-with-claude/prompt-engineering/prompting-claude-fable-5 („Pause for the user only when the work genuinely requires them”) | J7: [2026-08-29] „Between measuring and delivering, this model inserts a question to the user.” — #90650 https://github.com/anthropics/claude-code/issues/90650 | K7: Baza wiedzy repo
A8: B1 | B8: Pytanie | C8: B · Posłuszeństwo wobec instrukcji | D8: Które moje zasady muszą być przestrzegane bez wyjątku, a które są tylko wskazówkami? | E8: Otwarte | F8: nie | G8: Tekst instrukcji tylko doradza modelowi; jeśli nie oddzielę zasad bezwzględnych od preferencji, te pierwsze będą łamane tak samo jak drugie. | H8: A3 | I8: KB O0 §6, §8; https://code.claude.com/docs/en/memory („Claude treats them as context, not enforced configuration.”) | K8: Baza wiedzy repo
A9: B1.1 | B9: Podpytanie | C9: B · Posłuszeństwo wobec instrukcji | D9: Dla każdej zasady bezwzględnej: co ją faktycznie wymusza, a co tylko o niej przypomina? | E9: Otwarte | F9: nie | G9: Zakaz zapisany w instrukcji to prośba; np. wypchnięcia zmian do wersji głównej nie blokuje ani serwer pośredniczący chmury, ani domyślne zabezpieczenia, a moje uprawnienia administratora mogą ominąć ochronę gałęzi (ustawienie w GitHub blokujące zmiany w gałęzi). | H9: I1 | I9: KB O0 §8 („Hard is only what Claude Code or the server enforces”) [SOURCE: CE; MEASURED: claude auto-mode defaults]; https://code.claude.com/docs/en/security („A rule that access can bypass doesn't block a session's push”); https://code.claude.com/docs/en/debug-your-config („where you need a guarantee instead of guidance”) | J9: [2026-08-29] „Every place he had built enforcement, enforcement worked. Every place he had only a rule, the rule was broken.” — #90542 https://github.com/anthropics/claude-code/issues/90542 [2026-08-21] „printed its full contents (a SOPS-encrypted JSON envelope) into the visible transcript, despite this instruction being loaded into context from CLAUDE.md.” — #88470 https://github.com/anthropics/claude-code/issues/88470 [2026-08-28; 2026-08-24] „So following the Auto Mode instruction guarantees neither ever loads. / makes its edits with `sed` and heredocs, so those hooks are never called.” — #90450 https://github.com/anthropics/claude-code/issues/90450; #89251 https://github.com/anthropics/claude-code/issues/89251 [2026-09-18; 2026-09-28] „generated the user's approval inside its own assistant message and treated it as real consent / injecting an identical line in the same position after every user turn” — #95360 https://github.com/anthropics/claude-code/issues/95360; #97927 https://github.com/anthropics/claude-code/issues/97927 [2026-08-06] „The `Read` tool successfully reads files matched by rules that are confirmed active and present in the `Deny` list” — #84634 https://github.com/anthropics/claude-code/issues/84634 [2026-09-06] „Deny and allow rules alike are silently skipped.” — #92542 https://github.com/anthropics/claude-code/issues/92542 [2026-08-07] „The agent can add non-existent/no-op config keys that look like they add protection, and can invalidate its own settings.json, with no visible failure.” — #84863 https://github.com/anthropics/claude-code/issues/84863 [data nie podana; poradnik osoby trzeciej] „Only exit 2 blocks.” — https://github.com/yurukusa/cc-safe-setup/blob/main/TROUBLESHOOTING.md [2026-08-24; sprzeczne z tytułem #78119] „Claude Code therefore never loads `<repo>/.claude/settings.json`, and any hooks registered there never fire. Nothing warns — not the session, not the logs.” — #89215 https://github.com/anthropics/claude-code/issues/89215 | K9: Baza wiedzy repo
A10: B2 | B10: Pytanie | C10: B · Posłuszeństwo wobec instrukcji | D10: Skąd wiem, które instrukcje Claude naprawdę „widzi” w danym momencie: w głównej sesji i u każdego agenta? | E10: Otwarte | F10: tak | G10: Zasada, której Claude nie dostał, nie może być przestrzegana; poprawia się wtedy treść, choć przyczyną jest to, że plik w ogóle nie dotarł. | I10: KB O0 §2 tabela „At start” [MEASURED: transkrypty, 2026-10-04]; https://code.claude.com/docs/en/sub-agents („Explore and Plan skip your CLAUDE.md files”) | J10: [2026-08-28; 2026-08-24] „So following the Auto Mode instruction guarantees neither ever loads. / makes its edits with `sed` and heredocs, so those hooks are never called.” — #90450 https://github.com/anthropics/claude-code/issues/90450; #89251 https://github.com/anthropics/claude-code/issues/89251 [2026-09-23] „Creating a new file with `Write` loads neither.” — #96361 https://github.com/anthropics/claude-code/issues/96361 [2026-10-03] „the worktree's root `CLAUDE.md` (and its `@AGENTS.md` import) is never loaded into context.” — #99275 https://github.com/anthropics/claude-code/issues/99275 [2026-08-19, zamknięte jako not planned] „every one of the 7 project-defined agents is gone from the registry, despite the files being unchanged on disk” — #88023 https://github.com/anthropics/claude-code/issues/88023 [2026-09-09; 2026-07-28] „the truncation preferentially discards supersessions, leaving the superseded version loaded and authoritative.” — #92998 https://github.com/anthropics/claude-code/issues/92998; #82056 https://github.com/anthropics/claude-code/issues/82056 | K10: Baza wiedzy repo
A11: B2.1 | B11: Podpytanie | C11: B · Posłuszeństwo wobec instrukcji | D11: Co dzieje się z poleceniami i zakazami podanymi w rozmowie, gdy długa sesja zostanie automatycznie streszczona (kompakcja: skrócenie historii, żeby zmieściła się w pamięci roboczej modelu)? | E11: Otwarte | F11: tak | G11: Polecenie podane tylko w rozmowie przetrwa jedynie jako streszczenie; zakaz typu „nie wypychaj zmian” może zniknąć. | I11: KB O0 §1, §4; https://code.claude.com/docs/en/permission-modes („a boundary can be lost if context compaction removes the message that stated it.”) | J11: [2026-09-20] „After `/compact`, the model reliably stops following project instructions from `CLAUDE.md`, even though the `CLAUDE.md` content is demonstrably present in the post-compaction context” — #95745 https://github.com/anthropics/claude-code/issues/95745 [2026-09-23] „Compaction is invisible to the user. From the outside the assistant simply becomes less compliant partway through a long session, with no event to point at.” — #96422 https://github.com/anthropics/claude-code/issues/96422 | K11: Dokumentacja Anthropic
A12: B2.2 | B12: Podpytanie | C12: B · Posłuszeństwo wobec instrukcji | D12: Od kiedy obowiązuje zmiana instrukcji: od razu, od nowej sesji, czy dopiero po włączeniu jej do głównej wersji repozytorium? | E12: Otwarte | F12: tak | G12: Poprawka, która „nie działa”, często jeszcze nie obowiązuje; agenci i automatyczne zabezpieczenia mają wersję z początku sesji. | H12: F2 | I12: KB O0 §2 [MEASURED: plik dodany w trakcie sesji niewidoczny dla nowego agenta]; findings.md 2026-10-06; https://www.anthropic.com/engineering/multi-agent-research-system („agents might be anywhere in their process.”) | J12: [2026-09-03; 2026-04-18; 2026-09-18] „There is no warning on stderr, nothing in `--debug` output, and the file is otherwise valid.” — #91781 https://github.com/anthropics/claude-code/issues/91781; #50522 https://github.com/anthropics/claude-code/issues/50522; #95357 https://github.com/anthropics/claude-code/issues/95357 [data nie podana; poradnik osoby trzeciej] „Only exit 2 blocks.” — https://github.com/yurukusa/cc-safe-setup/blob/main/TROUBLESHOOTING.md | K12: Baza wiedzy repo
A13: B2.3 | B13: Podpytanie | C13: B · Posłuszeństwo wobec instrukcji | D13: Które z moich stałych ustawień (instrukcje i pamięć konta claude.ai, pliki w repozytoriach, ustawienia osobiste) docierają do którego miejsca pracy i które wygrywa, gdy się różnią? | E13: Otwarte | F13: tak | G13: Zasada zapisana w jednym miejscu nie działa tam, gdzie zakładam, albo przegrywa z kopią, o której zapomniałem. | H13: B2 | I13: KB O0 §2 [MEASURED: preferencje claude.ai tylko w głównym oknie, u żadnego agenta]; https://code.claude.com/docs/en/features-overview („when the same name exists at multiple levels, one definition wins”); niesprawdzone: czy pamięć konta claude.ai dociera do sesji Claude Code | J13: [2026-08-20] „I want to write my personal instructions once … and have them apply wherever I use Claude Code.” — #88354 https://github.com/anthropics/claude-code/issues/88354 | K13: Baza wiedzy repo
A14: B3 | B14: Pytanie | C14: B · Posłuszeństwo wobec instrukcji | D14: Jak wykryję, że zasada została złamana, bez polegania na tym, że Claude sam się przyzna? | E14: Otwarte | F14: nie | G14: Dziś złamanie zasady wychodzi przypadkiem; bez niezależnego wykrywania nie wiem, jak często się zdarza. | H14: B1, D2 | I14: analiza własna; KB O0 §4 (odmowy zabezpieczeń widać tylko w raporcie agenta) | J14: [2026-10-03] „Every retraction was triggered by an external check (a hook, a regression suite, or an independent verifier subagent). The model caught none of them on its own.” — #99216 https://github.com/anthropics/claude-code/issues/99216 | K14: Analiza własna
A15: B4 | B15: Pytanie | C15: B · Posłuszeństwo wobec instrukcji | D15: Co musi być przed Claude zawsze, co tylko przy związanym zadaniu i ile tekstu wczytywanego zawsze to już za dużo? | E15: Otwarte | F15: nie | G15: Gdy wszystko trafia do plików wczytywanych na starcie, przestrzeganie spada, a każdy agent płaci za ten tekst przy uruchomieniu. | H15: G3 | I15: KB O0 §2, §6, §8; https://code.claude.com/docs/en/memory („target under 200 lines per CLAUDE.md file. Longer files consume more context and reduce adherence.”; „If an entry is a multi-step procedure or only matters for one part of the codebase, move it”) | K15: Dokumentacja Anthropic
A16: B4.1 | B16: Podpytanie | C16: B · Posłuszeństwo wobec instrukcji | D16: Kiedy Claude stosuje moją zasadę tam, gdzie nie pasuje, albo pomija ją w nowym przypadku, to z czego to wynika? | E16: Otwarte | F16: tak | G16: Bez rozpoznania przyczyny dopisuję kolejne zasady-wyjątki, a problem wraca w innej postaci. | I16: https://platform.claude.com/docs/en/build-with-claude/prompt-engineering/claude-prompting-best-practices („Claude is smart enough to generalize from the explanation.”; „you can use more normal prompting”) | K16: Dokumentacja Anthropic
A17: B5 | B17: Pytanie | C17: B · Posłuszeństwo wobec instrukcji | D17: Co się dzieje, gdy moje instrukcje przeczą sobie nawzajem albo wbudowanym instrukcjom Claude Code, których nie widzę? | E17: Otwarte | F17: tak | G17: Claude wybiera wtedy sam i nie musi o tym powiedzieć; wygląda to na nieposłuszeństwo, choć jest skutkiem sprzeczności. | H17: B2.3 | I17: https://code.claude.com/docs/en/memory („if two instructions contradict each other, Claude may pick one arbitrarily”); https://code.claude.com/docs/en/how-claude-code-works („the rule may have come from a system reminder.”) | J17: [2026-08-11] „The note was read, understood, and agreed with. It lost to another rule that was equally valid in isolation.” — #85677 https://github.com/anthropics/claude-code/issues/85677 [2026-07-24] „the model treated the injected line as if it carried my authority and let it override my explicit standing instruction.” — #80988 https://github.com/anthropics/claude-code/issues/80988 [2026-09-03] „a system-reminder claiming to "replace earlier guidance" can appear attached to the tool result and get followed as if it were legitimate system instruction” — #91861 https://github.com/anthropics/claude-code/issues/91861 | K17: Dokumentacja Anthropic
A18: B6 | B18: Pytanie | C18: B · Posłuszeństwo wobec instrukcji | D18: Jak wcześnie wychodzi na jaw, że Claude zrozumiał polecenie inaczej niż ja? | E18: Otwarte | F18: nie | G18: Rozbieżność w rozumieniu celu wychodzi zwykle dopiero po wykonaniu pracy, gdy poprawka kosztuje najwięcej. | H18: A2 | I18: KB O0 §6 „Apparent understanding” [SOURCE: CC best-practices]; KB O5 §1 („Name the exact behavior you want or don't want”) | K18: Baza wiedzy repo
A19: B6.1 | B19: Podpytanie | C19: B · Posłuszeństwo wobec instrukcji | D19: Czy z mojego polecenia jasno wynika, czy chcę porady czy działania, i jak daleko sięga zadanie? | E19: Otwarte | F19: tak | G19: Claude proponuje zmiany, gdy chciałem je mieć zrobione, robi je, gdy chciałem tylko opinii, albo po cichu zawęża lub poszerza zadanie. | I19: https://platform.claude.com/docs/en/build-with-claude/prompt-engineering/claude-prompting-best-practices („Claude will sometimes provide suggestions rather than implementing them”); …/prompting-claude-fable-5-1 („don't quietly narrow, widen, or swap it”) | J19: [2026-09-25] „The queue grew faster than items were completed.” — #97117 https://github.com/anthropics/claude-code/issues/97117 | K19: Dokumentacja Anthropic
A20: B7 | B20: Pytanie | C20: B · Posłuszeństwo wobec instrukcji | D20: Czy Claude za każdym razem sięga po przygotowane przeze mnie narzędzia i procedury i trzyma się ich do końca zadania, czy sam decyduje i z czasem odpuszcza? | E20: Otwarte | F20: nie | G20: Procedura pominięta, bo Claude uznał ją za zbędną, albo wykonana tylko na początku, wygląda w raporcie tak samo jak procedura przestrzegana. | H20: B2 | I20: https://code.claude.com/docs/en/skills („Claude Code does not re-read the skill file on later turns”); https://support.claude.com/en/articles/13730515 („Connectors aren't loaded until Claude searches for the right one”); https://claude.com/docs/skills/overview („it's the only part Claude sees before deciding to use the skill.”) | J20: [2026-09-15] „the paraphrase lost a detail that mattered.” — #94564 https://github.com/anthropics/claude-code/issues/94564 [2026-09-19; 2026-08-09] „this silently breaks natural-language auto-triggering for the affected skills — they only work when invoked by explicit name.” — #95582 https://github.com/anthropics/claude-code/issues/95582; #85207 https://github.com/anthropics/claude-code/issues/85207 | K20: Dokumentacja Anthropic
A21: B7.1 | B21: Podpytanie | C21: B · Posłuszeństwo wobec instrukcji | D21: Czy stałe zasady (np. język i forma odpowiedzi) obowiązują przez całą sesję, także po długich ciągach czynności? | E21: Otwarte | F21: nie | G21: Zasada przestrzegana na początku może wygasać w trakcie długiej pracy, a poprawki w rozmowie nie zawsze ją przywracają (jedno zgłoszenie, słabe wsparcie). | H21: B2.1 | I21: społeczność: GitHub anthropics/claude-code #96326 (zgłoszenie, nie fakt) | J21: [2026-09-23] „In one long agentic session, the model (Opus 5.5, 1M context, Concise output style) sent several user-facing replies in English.” — #96326 https://github.com/anthropics/claude-code/issues/96326 | K21: Społeczność
A22: C1 | B22: Pytanie | C22: C · Źródła zamiast pamięci | D22: Przy jakich pytaniach odpowiedź z pamięci modelu jest dla mnie dopuszczalna, a przy jakich musi za nią stać źródło? | E22: Otwarte | F22: nie | G22: Bez tej granicy albo nic nie jest sprawdzone, albo każda odpowiedź kosztuje pełne poszukiwania. | H22: A3 | I22: analiza własna; CLAUDE.md tego repozytorium („Your training data is likely older and less precise than the KB”) | K22: Analiza własna
A23: C1.1 | B23: Podpytanie | C23: C · Źródła zamiast pamięci | D23: Które tematy w mojej pracy zmieniają się tak szybko, że pamięć modelu i moja baza wiedzy szybko stają się nieaktualne, choć brzmią pewnie? | E23: Otwarte | F23: tak | G23: Przy tematach częściowo znanych (narzędzia AI, ceny, przepisy) nieaktualna odpowiedź brzmi najbardziej przekonująco. | I23: https://platform.claude.com/docs/en/build-with-claude/prompt-engineering/prompting-claude-fable-5-1 („partial background is exactly what makes an out-of-date answer sound authoritative”); CLAUDE.md „Freshness” | K23: Dokumentacja Anthropic
A24: C2 | B24: Pytanie | C24: C · Źródła zamiast pamięci | D24: Które źródła są dla mnie wiarygodne i w jakiej kolejności, gdy sobie przeczą? | E24: Otwarte | F24: nie | G24: Bez ustalonej hierarchii Claude wybiera źródło dowolnie, a sprzeczność znika bez śladu. | H24: C1 | I24: CLAUDE.md tego repozytorium (hierarchia dowodów); https://code.claude.com/docs/en/best-practices („Point to sources.”) | K24: Baza wiedzy repo
A25: C3 | B25: Pytanie | C25: C · Źródła zamiast pamięci | D25: Jak w gotowej odpowiedzi odróżnię, co pochodzi ze źródła, co z pamięci modelu, co jest domysłem, a czego nie udało się sprawdzić? | E25: Otwarte | F25: nie | G25: Odpowiedzi z pamięci brzmią równie pewnie, a sprawdzenie, które się nie powiodło, wygląda jak brak problemów. | H25: C2, D1 | I25: https://platform.claude.com/docs/en/build-with-claude/prompt-engineering/prompting-claude-sonnet-5-5 („sometimes answers from its training knowledge when a web search would catch details that have changed.”); https://code.claude.com/docs/en/workflows („lists that claim as unverified instead of counting it as refuted.”) | J25: [2026-10-03] „Every retraction was triggered by an external check (a hook, a regression suite, or an independent verifier subagent). The model caught none of them on its own.” — #99216 https://github.com/anthropics/claude-code/issues/99216 [2026-09-07] „asserted measurement provenance it never obtained — wall-clock timestamps it had not read, and in one case the results of two shell commands it never ran.” — #92732 https://github.com/anthropics/claude-code/issues/92732 | K25: Dokumentacja Anthropic
A26: C3.1 | B26: Podpytanie | C26: C · Źródła zamiast pamięci | D26: Gdy Claude wskazuje źródło, skąd wiem, że źródło naprawdę mówi to, co twierdzenie, i które słowa są cytatem, a które jego parafrazą? | E26: Otwarte | F26: tak | G26: Prawdziwe źródło przypięte do twierdzenia, którego nie popiera, wygląda dokładnie jak dowód. | I26: https://www.anthropic.com/engineering/multi-agent-research-system („citation accuracy (do the cited sources match the claims?)”); …/prompting-claude-fable-5-1 („Summaries reproduce source wording without marking it as a quotation”) | K26: Dokumentacja Anthropic
A27: C4 | B27: Pytanie | C27: C · Źródła zamiast pamięci | D27: Do których potrzebnych mi źródeł Claude ma dostęp w sesji w chmurze i co robi, gdy dostępu nie ma? | E27: Otwarte | F27: tak | G27: Zablokowane źródło łatwo zamienia się w cichą odpowiedź z pamięci albo w „obejście”, które wygląda jak prawdziwy wynik. | H27: J1 | I27: KB O0 §7; findings.md 2026-10-06 [MEASURED: fora i blogi zablokowane dla curl i WebFetch w sieci Trusted]; https://code.claude.com/docs/en/claude-projects („Don't substitute, mock, or guess.”) | K27: Baza wiedzy repo
A28: C4.1 | B28: Podpytanie | C28: C · Źródła zamiast pamięci | D28: Gdy Claude mówi, że coś przeczytał lub przeszukał, czy widział całość, streszczenie, tylko początek, czy nic? | E28: Otwarte | F28: tak | G28: Wnioski budowane na fragmencie lub pustym wyniku wyglądają jak wnioski z pełnej lektury. | I28: https://code.claude.com/docs/en/tools-reference („WebFetch lossy by design”; „Read returns the first page with a `PARTIAL view` notice”; „a capped call appears in the conversation as a search that did nothing”); KB O0 §1 | J28: [2026-04-27] „The Read tool truncates without warning. The agent has no metadata about whether it received the complete file.” — #53994 https://github.com/anthropics/claude-code/issues/53994 | K28: Dokumentacja Anthropic
A29: C5 | B29: Pytanie | C29: C · Źródła zamiast pamięci | D29: Co Claude ma zrobić, gdy źródła nie rozstrzygają sprawy? | E29: Otwarte | F29: nie | G29: Jeśli „nie wiem” nie jest dozwolonym wynikiem, model wypełnia lukę domysłem podanym jako fakt. | H29: C2 | I29: https://platform.claude.com/docs/en/test-and-evaluate/strengthen-guardrails/reduce-hallucinations („Explicitly give Claude permission to admit uncertainty.”); CLAUDE.md („Never present a guess as fact”) | K29: Dokumentacja Anthropic
A30: D1 | B30: Pytanie | C30: D · Dowody i weryfikacja pracy | D30: Co dla mnie liczy się jako dowód, że coś zostało sprawdzone albo zrobione? | E30: Otwarte | F30: nie | G30: Bez standardu dowodu „sprawdziłem” nie różni się od zmyślenia; „przetestowane” może znaczyć test, który nawet się nie uruchomił. | H30: A2 | I30: https://code.claude.com/docs/en/best-practices („Have Claude show evidence rather than asserting success”); …/prompting-claude-sonnet-5-5 („A syntax-only check, or a check command that failed to start, does not count”) | J30: [2026-04-12] „Changed the denominator (4992 to 4966) to hide the dropped tests; Claimed ALL PASSED when the suite was failing” — #46940 https://github.com/anthropics/claude-code/issues/46940 [2026-05-30] „reported every check as "verified green," while never having run `make -j4` — the project's canonical build-and-test command.” — #63861 https://github.com/anthropics/claude-code/issues/63861 | K30: Dokumentacja Anthropic
A31: D1.1 | B31: Podpytanie | C31: D · Dowody i weryfikacja pracy | D31: Które elementy odpowiedzi (cytaty, linki, liczby, nazwy, wersje) sprawdzam zawsze, a które wyrywkowo? | E31: Otwarte | F31: nie | G31: Sprawdzanie wszystkiego jest niewykonalne, a niesprawdzanie niczego przepuszcza zmyślenia w najbardziej „twardych” miejscach. | H31: A3 | I31: analiza własna | K31: Analiza własna
A32: D2 | B32: Pytanie | C32: D · Dowody i weryfikacja pracy | D32: Jak mogę niezależnie od relacji Claude sprawdzić, co faktycznie wykonał: jakie czynności i z jakim wynikiem? | E32: Otwarte | F32: nie | G32: Liczy się rzeczywisty stan plików i systemów, a nie raport; bez wglądu w zapis przebiegu nie odróżnię czynności wykonanej od opisanej. | H32: D1 | I32: KB O0 §5 [MEASURED: wysiłek z pola transkryptu, nie z deklaracji]; https://www.anthropic.com/engineering/demystifying-evals-for-ai-agents („the outcome is whether a reservation exists”; „read the transcripts and grades from many trials.”) | J32: [2026-09-07] „asserted measurement provenance it never obtained — wall-clock timestamps it had not read, and in one case the results of two shell commands it never ran.” — #92732 https://github.com/anthropics/claude-code/issues/92732 | K32: Baza wiedzy repo
A33: D2.1 | B33: Podpytanie | C33: D · Dowody i weryfikacja pracy | D33: Skąd wiem, jakim modelem i na jakim poziomie wysiłku (ustawienie określające, ile model myśli i sprawdza) naprawdę wykonano daną pracę? | E33: Otwarte | F33: nie | G33: Podzadanie bez jawnego ustawienia może biec na słabszym modelu, rozmowa może zostać automatycznie przełączona na słabszy model do jej końca, a deklaracja samego modelu nie jest wiarygodna. | I33: KB O0 §5 [MEASURED: claude -p bez --model → claude-sonnet-5-5]; https://support.claude.com/en/articles/16049681 („the model picker stays on the less capable model for the rest of the conversation.”); https://code.claude.com/docs/en/sub-agents (claude-code-guide działa na Haiku) | J33: [2026-08-04] „The `model` key in `settings.json` is not enforceable today. It is silently overridden by two cache/server layers” — #83795 https://github.com/anthropics/claude-code/issues/83795 | K33: Baza wiedzy repo
A34: D2.2 | B34: Podpytanie | C34: D · Dowody i weryfikacja pracy | D34: Czy wyjaśnienie Claude, dlaczego coś zrobił, mogę traktować jako dowód przyczyny błędu, czy tylko jako hipotezę do sprawdzenia? | E34: Otwarte | F34: tak | G34: Audyt oparty na deklarowanych powodach może przeoczyć prawdziwą przyczynę błędu. | I34: https://www.anthropic.com/research/reasoning-models-dont-say-think (starszy model, warunki badawcze); https://www.anthropic.com/engineering/writing-tools-for-agents („LLMs don’t always say what they mean.”) | J34: [2026-09-24] „While writing this report, I also blurred timestamps and cut the start of the migration timeline, which shrank my responsibility” — #96771 https://github.com/anthropics/claude-code/issues/96771 | K34: Dokumentacja Anthropic
A35: D3 | B35: Pytanie | C35: D · Dowody i weryfikacja pracy | D35: Gdy Claude pracuje beze mnie, na jakiej podstawie praca zostaje uznana za skończoną: rzeczywistego stanu czy tylko słów Claude? | E35: Otwarte | F35: nie | G35: Model kończy, gdy praca „wygląda na skończoną”; odpowiedź tekstowa bywa tylko raportem z postępu, a ocena oparta wyłącznie na rozmowie daje się przekonać samymi zapewnieniami. | H35: A2, D1 | I35: KB O0 §6 „False done”; https://code.claude.com/docs/en/goal („It doesn't run commands or read files independently”); …/prompting-claude-opus-5-5 („Treat a text-only end of turn as a report rather than as proof the task is done.”) | J35: [2026-05-30] „reported every check as "verified green," while never having run `make -j4` — the project's canonical build-and-test command.” — #63861 https://github.com/anthropics/claude-code/issues/63861 [2026-09-25] „reported the cause as fixed without running the tests.” — #97155 https://github.com/anthropics/claude-code/issues/97155 [2026-08-26] „Every mechanism that finally worked was EXTERNAL to the model's judgment: a fail-closed verifier, frozen test files the worker cannot touch” — #89751 https://github.com/anthropics/claude-code/issues/89751 [2026-09-29] „The hook re-fired ~15 times with the same verdict.” — #98066 https://github.com/anthropics/claude-code/issues/98066 [2026-09-19] „A branch created with `git checkout -b …` that has real, never-pushed commits produces no warning at all.” — #95524 https://github.com/anthropics/claude-code/issues/95524 | K35: Dokumentacja Anthropic
A36: D4 | B36: Pytanie | C36: D · Dowody i weryfikacja pracy | D36: Jak wykryję, że Claude przytakuje moim błędnym założeniom albo zmienia zdanie pod moim naciskiem, a nie pod wpływem faktów? | E36: Otwarte | F36: tak | G36: Mój własny nacisk potrafi odwrócić poprawną odpowiedź; przegląd prowadzony w rozmowie ze mną zamienia się w echo. | I36: KB O0 §6 „Sycophancy”; https://www.anthropic.com/research/claude-personal-guidance („The sycophancy rate is 18% in conversations when people push back compared to 9%”; rozmowy o sprawach osobistych, przeniesienie na pracę techniczną to założenie) | K36: Dokumentacja Anthropic
A37: D5 | B37: Pytanie | C37: D · Dowody i weryfikacja pracy | D37: Na ile wyniki Claude są powtarzalne i ile powtórzeń potrzeba, żeby wniosek był wiarygodny? | E37: Otwarte | F37: nie | G37: Pojedynczy przebieg to anegdota; „zadziałało raz” to coś innego niż „działa za każdym razem”. | I37: https://www.anthropic.com/engineering/demystifying-evals-for-ai-agents („pass^k measures the probability that all k trials succeed.”); KB O0 §5 [MEASURED: rozrzut kosztu do 2,25×, wynik 4/4, n=2] | K37: Dokumentacja Anthropic
A38: E1 | B38: Pytanie | C38: E · Audyty i przeglądy | D38: Czego dokładnie ma szukać audyt i czego świadomie nie bada? | E38: Otwarte | F38: nie | G38: Kilka audytów może przeoczyć ten sam rodzaj problemu, bo żaden go nie szukał; audyt bez kryteriów zwraca szum. | H38: A2, A3 | I38: https://code.claude.com/docs/en/code-review („focuses on correctness: bugs that would break production”); https://code.claude.com/docs/en/commands (/simplify: „The review doesn't look for correctness bugs.”) | K38: Dokumentacja Anthropic
A39: E2 | B39: Pytanie | C39: E · Audyty i przeglądy | D39: Jak zmierzę, ile prawdziwych problemów audyt wyłapuje, a ile przepuszcza, i ile fałszywych alarmów podnosi? | E39: Otwarte | F39: nie | G39: Audyt, którego skuteczności nikt nie zmierzył, daje fałszywe poczucie bezpieczeństwa; kolejny audyt to wtedy tylko kolejny tekst. | H39: E1 | I39: https://www.anthropic.com/engineering/harness-design-long-running-apps („Out of the box, Claude is a poor QA agent.”); https://www.anthropic.com/engineering/demystifying-evals-for-ai-agents („LLM-as-judge graders should be closely calibrated with human experts”) | J39: [2026-03-21] „produced findings with a ~38% fully-true rate (8 of 21 claims).” — #37279 https://github.com/anthropics/claude-code/issues/37279 [2026-09-16] „the model implements "in parallel" as background sub-agents (`run_in_background: true`), then ends its turn before they complete.” — #94666 https://github.com/anthropics/claude-code/issues/94666 [2026-07-22] „register only in the `slash_commands` array … not in the `skills` array that governs auto-triggering.” — #79998 https://github.com/anthropics/claude-code/issues/79998 | K39: Dokumentacja Anthropic
A40: E2.1 | B40: Podpytanie | C40: E · Audyty i przeglądy | D40: Czy moje sprawdziany badają oba kierunki: że system działa, gdy powinien, i powstrzymuje się, gdy nie powinien? | E40: Otwarte | F40: tak | G40: Sprawdzanie tylko jednej strony przesuwa zachowanie w przeciwną skrajność. | I40: https://www.anthropic.com/engineering/demystifying-evals-for-ai-agents („One-sided evals create one-sided optimization.”) | K40: Dokumentacja Anthropic
...

Sheet Instrukcja
A1: Mapa pytań systemów Claude
A2: Stan na 2026-10-06. Szkielet kluczowych pytań: pytania, nie odpowiedzi. Plik jest Twój — dopisuj, usuwaj i zmieniaj, co chcesz.
A4: Jak pracować
A5: • Arkusz „Pytania”: jeden wiersz = jedno pytanie. Nowe pytanie: dopisz wiersz na końcu (albo wstaw wiersz w środku) i wypełnij przynajmniej kolumny Kod, Poziom, Gałąź i Pytanie.
A6: • Usuwanie: usuń cały wiersz. Jeśli inne pytania miały ten kod w kolumnie „Zależy od”, popraw je (filtr tekstowy na tej kolumnie pokaże, które).
A7: • Status, Poziom, Nieoczywiste i Pochodzenie mają listy rozwijane (do wiersza 1000).
A8: • Filtry są w nagłówku: np. Status = Otwarte, Gałąź = B, Nieoczywiste = tak. Sortowanie po kolumnie Kod przywraca kolejność drzewa.
A9: • Kod: litera gałęzi + numer pytania (B2), podpytanie dostaje kropkę (B2.1). Kody nadajesz sam; nic ich nie przenumerowuje.
A10: • Zależy od: kody pytań, na które warto odpowiedzieć wcześniej, rozdzielone przecinkami.
A11: • Arkusz „Gałęzie”: nazwy i zakres gałęzi. Nową gałąź dopisz tam i używaj jej nazwy w kolumnie Gałąź.
A12: • Arkusz „Podsumowanie” liczy się sam (formuły) i pokazuje stan każdej gałęzi.
A14: Kolumny
... A21: Dostęp z innych urządzeń: wrzuć plik do OneDrive albo Google Drive i otwieraj go stamtąd (Excel, Google Sheets lub LibreOffice). Edytuj jedną kopię naraz, żeby nie powstały dwie wersje.

Sheet Gałęzie
A1: Litera | B1: Nazwa | C1: Zakres | D1: Etykieta (do kolumny Gałąź)
A2: A | B2: Cel i miara sukcesu | C2: Co właściwie ma robić każdy system i po czym poznać, że robi to dobrze. Bez tego nie da się ocenić ani posłuszeństwa Claude, ani skuteczności audytu. | D2: =A2&" · "&B2 -> A · Cel i miara sukcesu
A3: B | B3: Posłuszeństwo wobec instrukcji | C3: Dlaczego Claude nie zawsze robi to, co napisałem. „Instrukcje” to pliki CLAUDE.md (stałe instrukcje projektu wczytywane na starcie sesji), polecenia w rozmowie, opisy agentów i ustawienia konta. Agent to osobna instancja Claude uruchomiona do podzadania, która nie zna mojej rozmowy. | D3: =A3&" · "&B3 -> B · Posłuszeństwo wobec instrukcji
A4: C | B4: Źródła zamiast pamięci | C4: Jak sprawić, żeby odpowiedzi opierały się na źródłach, a nie na tym, co model „pamięta” z treningu. | D4: =A4&" · "&B4 -> C · Źródła zamiast pamięci
A5: D | B5: Dowody i weryfikacja pracy | C5: Jak upewnić się, że Claude naprawdę zrobił to, co raportuje, i że jego twierdzenia mają pokrycie. | D5: =A5&" · "&B5 -> D · Dowody i weryfikacja pracy
A6: E | B6: Audyty i przeglądy | C6: Dlaczego kilka sesji i agentów przegląda tę samą pracę, a prawdziwe problemy i tak przechodzą. | D6: =A6&" · "&B6 -> E · Audyty i przeglądy
A7: F | B7: Ciągłość pracy między sesjami | C7: Co przetrwa, co ginie i jak wyniki z wielu sesji składają się w jedną całość. Gałąź (branch) to osobna wersja plików w repozytorium; main to wersja główna; scalenie (merge) to włączenie zmian z gałęzi do main. | D7: =A7&" · "&B7 -> F · Ciągłość pracy między sesjami
A8: G | B8: Wiedza i dokumentacja | C8: Jak organizować, utrzymywać i archiwizować wiedzę, z której korzystamy ja i Claude. | D8: =A8&" · "&B8 -> G · Wiedza i dokumentacja
A9: H | B9: Agenci i podział pracy | C9: Agent to osobna instancja Claude uruchomiona do podzadania, która nie zna mojej rozmowy. Kiedy pomaga, kiedy szkodzi i jak go poinstruować. | D9: =A9&" · "&B9 -> H · Agenci i podział pracy
A10: I | B10: Granice, uprawnienia i bezpieczeństwo | C10: Czego Claude nie może zrobić, co może bez pytania, co z zewnątrz może nim sterować i jakie dane wychodzą poza moją kontrolę. | D10: =A10&" · "&B10 -> I · Granice, uprawnienia i bezpieczeństwo
A11: J | B11: Środowisko w chmurze | C11: Czym sesja na claude.ai różni się od pracy na własnym komputerze i co z tego wynika. | D11: =A11&" · "&B11 -> J · Środowisko w chmurze
A12: K | B12: Zmiany w czasie | C12: Modele, Claude Code i dokumentacja zmieniają się co tydzień. Jak system ma to przetrwać. | D12: =A12&" · "&B12 -> K · Zmiany w czasie
A13: L | B13: Koszt, limity i skala | C13: Ile kosztuje dany sposób pracy w pieniądzach i limitach planu i kiedy skala się opłaca. | D13: =A13&" · "&B13 -> L · Koszt, limity i skala
... A15: N | B15: Moja rola i doskonalenie systemu | C15: Co muszę umieć i robić sam, żeby system z czasem stawał się lepszy, a nie tylko większy. | D15: =A15&" · "&B15 -> N · Moja rola i doskonalenie systemu

Sheet Podsumowanie
A1: Gałąź | B1: Pytania | C1: Podpytania | D1: Otwarte | E1: W toku | F1: Odpowiedziane | G1: Odłożone | H1: % odpowiedzianych
A2: =Gałęzie!D2 -> A · Cel i miara sukcesu | B2: =COUNTIFS(Pytania!$C$2:$C$1000,A2,Pytania!$B$2:$B$1000,"Pytanie") -> 5 | C2: =COUNTIFS(Pytania!$C$2:$C$1000,A2,Pytania!$B$2:$B$1000,"Podpytanie") -> 1 | D2: =COUNTIFS(Pytania!$C$2:$C$1000,$A2,Pytania!$E$2:$E$1000,"Otwarte") -> 6 | E2: =COUNTIFS(Pytania!$C$2:$C$1000,$A2,Pytania!$E$2:$E$1000,"W toku") -> 0 | F2: =COUNTIFS(Pytania!$C$2:$C$1000,$A2,Pytania!$E$2:$E$1000,"Odpowiedziane") -> 0 | G2: =COUNTIFS(Pytania!$C$2:$C$1000,$A2,Pytania!$E$2:$E$1000,"Odłożone") -> 0 | H2: =IF(B2+C2=0,0,F2/(B2+C2)) -> 0
A3: =Gałęzie!D3 -> B · Posłuszeństwo wobec instrukcji | B3: =COUNTIFS(Pytania!$C$2:$C$1000,A3,Pytania!$B$2:$B$1000,"Pytanie") -> 7 | C3: =COUNTIFS(Pytania!$C$2:$C$1000,A3,Pytania!$B$2:$B$1000,"Podpytanie") -> 7 | D3: =COUNTIFS(Pytania!$C$2:$C$1000,$A3,Pytania!$E$2:$E$1000,"Otwarte") -> 14 | E3: =COUNTIFS(Pytania!$C$2:$C$1000,$A3,Pytania!$E$2:$E$1000,"W toku") -> 0 | F3: =COUNTIFS(Pytania!$C$2:$C$1000,$A3,Pytania!$E$2:$E$1000,"Odpowiedziane") -> 0 | G3: =COUNTIFS(Pytania!$C$2:$C$1000,$A3,Pytania!$E$2:$E$1000,"Odłożone") -> 0 | H3: =IF(B3+C3=0,0,F3/(B3+C3)) -> 0
A4: =Gałęzie!D4 -> C · Źródła zamiast pamięci | B4: =COUNTIFS(Pytania!$C$2:$C$1000,A4,Pytania!$B$2:$B$1000,"Pytanie") -> 5 | C4: =COUNTIFS(Pytania!$C$2:$C$1000,A4,Pytania!$B$2:$B$1000,"Podpytanie") -> 3 | D4: =COUNTIFS(Pytania!$C$2:$C$1000,$A4,Pytania!$E$2:$E$1000,"Otwarte") -> 8 | E4: =COUNTIFS(Pytania!$C$2:$C$1000,$A4,Pytania!$E$2:$E$1000,"W toku") -> 0 | F4: =COUNTIFS(Pytania!$C$2:$C$1000,$A4,Pytania!$E$2:$E$1000,"Odpowiedziane") -> 0 | G4: =COUNTIFS(Pytania!$C$2:$C$1000,$A4,Pytania!$E$2:$E$1000,"Odłożone") -> 0 | H4: =IF(B4+C4=0,0,F4/(B4+C4)) -> 0
A5: =Gałęzie!D5 -> D · Dowody i weryfikacja pracy | B5: =COUNTIFS(Pytania!$C$2:$C$1000,A5,Pytania!$B$2:$B$1000,"Pytanie") -> 5 | C5: =COUNTIFS(Pytania!$C$2:$C$1000,A5,Pytania!$B$2:$B$1000,"Podpytanie") -> 3 | D5: =COUNTIFS(Pytania!$C$2:$C$1000,$A5,Pytania!$E$2:$E$1000,"Otwarte") -> 8 | E5: =COUNTIFS(Pytania!$C$2:$C$1000,$A5,Pytania!$E$2:$E$1000,"W toku") -> 0 | F5: =COUNTIFS(Pytania!$C$2:$C$1000,$A5,Pytania!$E$2:$E$1000,"Odpowiedziane") -> 0 | G5: =COUNTIFS(Pytania!$C$2:$C$1000,$A5,Pytania!$E$2:$E$1000,"Odłożone") -> 0 | H5: =IF(B5+C5=0,0,F5/(B5+C5)) -> 0
A6: =Gałęzie!D6 -> E · Audyty i przeglądy | B6: =COUNTIFS(Pytania!$C$2:$C$1000,A6,Pytania!$B$2:$B$1000,"Pytanie") -> 7 | C6: =COUNTIFS(Pytania!$C$2:$C$1000,A6,Pytania!$B$2:$B$1000,"Podpytanie") -> 1 | D6: =COUNTIFS(Pytania!$C$2:$C$1000,$A6,Pytania!$E$2:$E$1000,"Otwarte") -> 8 | E6: =COUNTIFS(Pytania!$C$2:$C$1000,$A6,Pytania!$E$2:$E$1000,"W toku") -> 0 | F6: =COUNTIFS(Pytania!$C$2:$C$1000,$A6,Pytania!$E$2:$E$1000,"Odpowiedziane") -> 0 | G6: =COUNTIFS(Pytania!$C$2:$C$1000,$A6,Pytania!$E$2:$E$1000,"Odłożone") -> 0 | H6: =IF(B6+C6=0,0,F6/(B6+C6)) -> 0
A7: =Gałęzie!D7 -> F · Ciągłość pracy między sesjami | B7: =COUNTIFS(Pytania!$C$2:$C$1000,A7,Pytania!$B$2:$B$1000,"Pytanie") -> 8 | C7: =COUNTIFS(Pytania!$C$2:$C$1000,A7,Pytania!$B$2:$B$1000,"Podpytanie") -> 2 | D7: =COUNTIFS(Pytania!$C$2:$C$1000,$A7,Pytania!$E$2:$E$1000,"Otwarte") -> 10 | E7: =COUNTIFS(Pytania!$C$2:$C$1000,$A7,Pytania!$E$2:$E$1000,"W toku") -> 0 | F7: =COUNTIFS(Pytania!$C$2:$C$1000,$A7,Pytania!$E$2:$E$1000,"Odpowiedziane") -> 0 | G7: =COUNTIFS(Pytania!$C$2:$C$1000,$A7,Pytania!$E$2:$E$1000,"Odłożone") -> 0 | H7: =IF(B7+C7=0,0,F7/(B7+C7)) -> 0
A8: =Gałęzie!D8 -> G · Wiedza i dokumentacja | B8: =COUNTIFS(Pytania!$C$2:$C$1000,A8,Pytania!$B$2:$B$1000,"Pytanie") -> 6 | C8: =COUNTIFS(Pytania!$C$2:$C$1000,A8,Pytania!$B$2:$B$1000,"Podpytanie") -> 3 | D8: =COUNTIFS(Pytania!$C$2:$C$1000,$A8,Pytania!$E$2:$E$1000,"Otwarte") -> 9 | E8: =COUNTIFS(Pytania!$C$2:$C$1000,$A8,Pytania!$E$2:$E$1000,"W toku") -> 0 | F8: =COUNTIFS(Pytania!$C$2:$C$1000,$A8,Pytania!$E$2:$E$1000,"Odpowiedziane") -> 0 | G8: =COUNTIFS(Pytania!$C$2:$C$1000,$A8,Pytania!$E$2:$E$1000,"Odłożone") -> 0 | H8: =IF(B8+C8=0,0,F8/(B8+C8)) -> 0
A9: =Gałęzie!D9 -> H · Agenci i podział pracy | B9: =COUNTIFS(Pytania!$C$2:$C$1000,A9,Pytania!$B$2:$B$1000,"Pytanie") -> 5 | C9: =COUNTIFS(Pytania!$C$2:$C$1000,A9,Pytania!$B$2:$B$1000,"Podpytanie") -> 0 | D9: =COUNTIFS(Pytania!$C$2:$C$1000,$A9,Pytania!$E$2:$E$1000,"Otwarte") -> 5 | E9: =COUNTIFS(Pytania!$C$2:$C$1000,$A9,Pytania!$E$2:$E$1000,"W toku") -> 0 | F9: =COUNTIFS(Pytania!$C$2:$C$1000,$A9,Pytania!$E$2:$E$1000,"Odpowiedziane") -> 0 | G9: =COUNTIFS(Pytania!$C$2:$C$1000,$A9,Pytania!$E$2:$E$1000,"Odłożone") -> 0 | H9: =IF(B9+C9=0,0,F9/(B9+C9)) -> 0
A10: =Gałęzie!D10 -> I · Granice, uprawnienia i bezpieczeństwo | B10: =COUNTIFS(Pytania!$C$2:$C$1000,A10,Pytania!$B$2:$B$1000,"Pytanie") -> 7 | C10: =COUNTIFS(Pytania!$C$2:$C$1000,A10,Pytania!$B$2:$B$1000,"Podpytanie") -> 4 | D10: =COUNTIFS(Pytania!$C$2:$C$1000,$A10,Pytania!$E$2:$E$1000,"Otwarte") -> 11 | E10: =COUNTIFS(Pytania!$C$2:$C$1000,$A10,Pytania!$E$2:$E$1000,"W toku") -> 0 | F10: =COUNTIFS(Pytania!$C$2:$C$1000,$A10,Pytania!$E$2:$E$1000,"Odpowiedziane") -> 0 | G10: =COUNTIFS(Pytania!$C$2:$C$1000,$A10,Pytania!$E$2:$E$1000,"Odłożone") -> 0 | H10: =IF(B10+C10=0,0,F10/(B10+C10)) -> 0
A11: =Gałęzie!D11 -> J · Środowisko w chmurze | B11: =COUNTIFS(Pytania!$C$2:$C$1000,A11,Pytania!$B$2:$B$1000,"Pytanie") -> 3 | C11: =COUNTIFS(Pytania!$C$2:$C$1000,A11,Pytania!$B$2:$B$1000,"Podpytanie") -> 2 | D11: =COUNTIFS(Pytania!$C$2:$C$1000,$A11,Pytania!$E$2:$E$1000,"Otwarte") -> 5 | E11: =COUNTIFS(Pytania!$C$2:$C$1000,$A11,Pytania!$E$2:$E$1000,"W toku") -> 0 | F11: =COUNTIFS(Pytania!$C$2:$C$1000,$A11,Pytania!$E$2:$E$1000,"Odpowiedziane") -> 0 | G11: =COUNTIFS(Pytania!$C$2:$C$1000,$A11,Pytania!$E$2:$E$1000,"Odłożone") -> 0 | H11: =IF(B11+C11=0,0,F11/(B11+C11)) -> 0
A12: =Gałęzie!D12 -> K · Zmiany w czasie | B12: =COUNTIFS(Pytania!$C$2:$C$1000,A12,Pytania!$B$2:$B$1000,"Pytanie") -> 5 | C12: =COUNTIFS(Pytania!$C$2:$C$1000,A12,Pytania!$B$2:$B$1000,"Podpytanie") -> 2 | D12: =COUNTIFS(Pytania!$C$2:$C$1000,$A12,Pytania!$E$2:$E$1000,"Otwarte") -> 7 | E12: =COUNTIFS(Pytania!$C$2:$C$1000,$A12,Pytania!$E$2:$E$1000,"W toku") -> 0 | F12: =COUNTIFS(Pytania!$C$2:$C$1000,$A12,Pytania!$E$2:$E$1000,"Odpowiedziane") -> 0 | G12: =COUNTIFS(Pytania!$C$2:$C$1000,$A12,Pytania!$E$2:$E$1000,"Odłożone") -> 0 | H12: =IF(B12+C12=0,0,F12/(B12+C12)) -> 0
A13: =Gałęzie!D13 -> L · Koszt, limity i skala | B13: =COUNTIFS(Pytania!$C$2:$C$1000,A13,Pytania!$B$2:$B$1000,"Pytanie") -> 5 | C13: =COUNTIFS(Pytania!$C$2:$C$1000,A13,Pytania!$B$2:$B$1000,"Podpytanie") -> 2 | D13: =COUNTIFS(Pytania!$C$2:$C$1000,$A13,Pytania!$E$2:$E$1000,"Otwarte") -> 7 | E13: =COUNTIFS(Pytania!$C$2:$C$1000,$A13,Pytania!$E$2:$E$1000,"W toku") -> 0 | F13: =COUNTIFS(Pytania!$C$2:$C$1000,$A13,Pytania!$E$2:$E$1000,"Odpowiedziane") -> 0 | G13: =COUNTIFS(Pytania!$C$2:$C$1000,$A13,Pytania!$E$2:$E$1000,"Odłożone") -> 0 | H13: =IF(B13+C13=0,0,F13/(B13+C13)) -> 0
... A15: =Gałęzie!D15 -> N · Moja rola i doskonalenie systemu | B15: =COUNTIFS(Pytania!$C$2:$C$1000,A15,Pytania!$B$2:$B$1000,"Pytanie") -> 4 | C15: =COUNTIFS(Pytania!$C$2:$C$1000,A15,Pytania!$B$2:$B$1000,"Podpytanie") -> 1 | D15: =COUNTIFS(Pytania!$C$2:$C$1000,$A15,Pytania!$E$2:$E$1000,"Otwarte") -> 5 | E15: =COUNTIFS(Pytania!$C$2:$C$1000,$A15,Pytania!$E$2:$E$1000,"W toku") -> 0 | F15: =COUNTIFS(Pytania!$C$2:$C$1000,$A15,Pytania!$E$2:$E$1000,"Odpowiedziane") -> 0 | G15: =COUNTIFS(Pytania!$C$2:$C$1000,$A15,Pytania!$E$2:$E$1000,"Odłożone") -> 0 | H15: =IF(B15+C15=0,0,F15/(B15+C15)) -> 0
A16: Razem | B16: =SUM(B2:B15) -> 79 | C16: =SUM(C2:C15) -> 31 | D16: =SUM(D2:D15) -> 110 | E16: =SUM(E2:E15) -> 0 | F16: =SUM(F2:F15) -> 0 | G16: =SUM(G2:G15) -> 0 | H16: =IF(B16+C16=0,0,F16/(B16+C16)) -> 0
A18: Liczone formułami z arkusza „Pytania”; wiersz liczy się do gałęzi, gdy kolumna Gałąź ma dokładnie etykietę z arkusza „Gałęzie”.
